<?xml version="1.0"?>
<robot name="robot_kol" xmlns:xacro="http://ros.org/wiki/xacro">
<<<<<<< HEAD
    <link name="world"/>

    <joint name="fixed" type="fixed">
        <parent link="world"/>
        <child link="link1"/>
    </joint>
=======
>>>>>>> bec217401a3e4cc5acd7a5ab1d1549c9870abb62

    <!-- Link 1 -->
    <link name="link1">
        <visual>
            <origin xyz="0 0 0" rpy="0 0 0"/>
            <geometry>
                <mesh filename="package://robotik_kol_pkg/meshes/chain_link1.stl" scale="0.001 0.001 0.001"/>
            </geometry>
            <material name="green">
                <color rgba="0.0 0.8 0.0 1.0"/>
            </material>
        </visual>

        <collision>
            <origin xyz="0 0 0" rpy="0 0 0"/>
            <geometry>
                <mesh filename="package://robotik_kol_pkg/meshes/chain_link1.stl" scale="0.001 0.001 0.001"/>
            </geometry>
        </collision>

        <inertial>
            <origin xyz="3.0876154e-04 0.0000000e+00 -1.2176461e-04"/>
            <mass value="7.9119962e-02"/>
            <inertia ixx="1.2505234e-05" ixy="0.0" ixz="-1.7855208e-07"
                     iyy="2.1898364e-05" iyz="0.0"
                     izz="1.9267361e-05"/>
        </inertial>
    </link>

<<<<<<< HEAD
        <!-- Joint 0 -->
<!--    <joint name="joint0" type="fixed">
        <parent link="world"/>
        <child link="link1"/>
    </joint>-->

=======
>>>>>>> bec217401a3e4cc5acd7a5ab1d1549c9870abb62
    <!-- Joint 1 -->
    <joint name="joint1" type="revolute">
        <parent link="link1"/>
        <child link="link2"/>
        <origin xyz="0.012 0.0 0.017" rpy="0 0 0"/>
        <axis xyz="0 0 1"/>
        <limit velocity="4.8" effort="1" lower="${-pi*0.9}" upper="${pi*0.9}" />
    </joint>

    <!--  Link 2 -->
    <link name="link2">
        <visual>
            <origin xyz="0 0 0.019" rpy="0 0 0"/>
            <geometry>
                <mesh filename="package://robotik_kol_pkg/meshes/chain_link2.stl" scale="0.001 0.001 0.001"/>
            </geometry>
            <material name="grey">
                <color rgba="0.5 0.5 0.5 1.0"/>
            </material>
        </visual>

        <collision>
            <origin xyz="0 0 0.019" rpy="0 0 0"/>
            <geometry>
                <mesh filename="package://robotik_kol_pkg/meshes/chain_link2.stl" scale="0.001 0.001 0.001"/>
            </geometry>
        </collision>

        <inertial>
            <origin xyz="-3.0184870e-04 5.4043684e-04 ${0.018 + 2.9433464e-02}" />
            <mass value="9.8406837e-02"/>
            <inertia ixx="3.4543422e-05" ixy="-1.6031095e-08" ixz="-3.8375155e-07"
                     iyy="3.2689329e-05" iyz="2.8511935e-08"
                     izz="1.8850320e-05"/>
        </inertial>
    </link>

    <!--  Joint 2 -->
    <joint name="joint2" type="revolute">
        <parent link="link2"/>
        <child link="link3"/>
        <origin xyz="0.0 0.0 0.0595" rpy="0 0 0"/>
        <axis xyz="0 1 0"/>
        <limit velocity="4.8" effort="1" lower="${-pi*0.57}" upper="${pi*0.5}" />
    </joint>

    <!--  Link 3 -->
    <link name="link3">
        <visual>
            <origin xyz="0 0 0" rpy="0 0 0"/>
            <geometry>
                <mesh filename="package://robotik_kol_pkg/meshes/chain_link3.stl" scale="0.001 0.001 0.001"/>
            </geometry>
            <material name="grey">
                <color rgba="0.5 0.5 0.5 1.0"/>
            </material>
        </visual>

        <collision>
            <origin xyz="0 0 0" rpy="0 0 0"/>
            <geometry>
                <mesh filename="package://robotik_kol_pkg/meshes/chain_link3.stl" scale="0.001 0.001 0.001"/>
            </geometry>
        </collision>

        <inertial>
            <origin xyz="1.0308393e-02 3.7743363e-04 1.0170197e-01"/>
            <mass value="1.3850917e-01"/>
            <inertia ixx="3.3055381e-04" ixy="-9.7940978e-08" ixz="-3.8505711e-05"
                     iyy="3.4290447e-04" iyz="-1.5717516e-06"
                     izz="6.0346498e-05"/>
        </inertial>
    </link>

    <!--  Joint 3 -->
    <joint name="joint3" type="revolute">
        <parent link="link3"/>
        <child link="link4"/>
        <origin xyz="0.024 0 0.128" rpy="0 0 0"/>
        <axis xyz="0 1 0"/>
        <limit velocity="4.8" effort="1" lower="${-pi*0.3}" upper="${pi*0.44}" />
    </joint>

    <!--  Link 4 -->
    <link name="link4">
        <visual>
            <origin xyz="0 0 0" rpy="0 0 0"/>
            <geometry>
                <mesh filename="package://robotik_kol_pkg/meshes/chain_link4.stl" scale="0.001 0.001 0.001"/>
            </geometry>
            <material name="grey">
                <color rgba="0.5 0.5 0.5 1.0"/>
            </material>
        </visual>

        <collision>
            <origin xyz="0 0 0" rpy="0 0 0"/>
            <geometry>
                <mesh filename="package://robotik_kol_pkg/meshes/chain_link4.stl" scale="0.001 0.001 0.001"/>
            </geometry>
        </collision>

        <inertial>
            <origin xyz="9.0909590e-02 3.8929816e-04 2.2413279e-04"/>
            <mass value="1.3274562e-01"/>
            <inertia ixx="3.0654178e-05" ixy="-1.2764155e-06" ixz="-2.6874417e-07"
                     iyy="2.4230292e-04" iyz="1.1559550e-08"
                     izz="2.5155057e-04"/>
        </inertial>
    </link>

    <!--  Joint 4 -->
    <joint name="joint4" type="revolute">
        <parent link="link4"/>
        <child link="link5"/>
        <origin xyz="0.124 0.0 0.0" rpy="0 0 0"/>
        <axis xyz="0 1 0"/>
        <limit velocity="4.8" effort="1" lower="${-pi*0.57}" upper="${pi*0.65}" />
    </joint>

    <!--  Link 5 -->
    <link name="link5">
        <visual>
            <origin xyz="0 0 0" rpy="0 0 0"/>
            <geometry>
                <mesh filename="package://robotik_kol_pkg/meshes/chain_link5.stl" scale="0.001 0.001 0.001"/>
            </geometry>
            <material name="grey">
                <color rgba="0.5 0.5 0.5 1.0"/>
            </material>
        </visual>

        <collision>
            <origin xyz="0 0 0" rpy="0 0 0"/>
            <geometry>
                <mesh filename="package://robotik_kol_pkg/meshes/chain_link5.stl" scale="0.001 0.001 0.001"/>
            </geometry>
        </collision>

        <inertial>
            <origin xyz="4.4206755e-02 3.6839985e-07 8.9142216e-03"/>
            <mass value="1.4327573e-01"/>
            <inertia ixx="8.0870749e-05" ixy="0.0" ixz="-1.0157896e-06"
                     iyy="7.5980465e-05" iyz="0.0"
                     izz="9.3127351e-05"/>
        </inertial>
    </link>

    <!--  Gripper joint -->
    <joint name="gripper" type="prismatic">
        <parent link="link5"/>
        <child link="gripper_link"/>
        <origin xyz="0.0817 0.021 0.0" rpy="0 0 0"/>
        <axis xyz="0 1 0"/>
        <limit velocity="4.8" effort="1" lower="-0.010" upper="0.019"/>
    </joint>

    <!--  Gripper link -->
    <link name="gripper_link">
        <visual>
            <origin xyz="0.0 0.0 0" rpy="0 0 0"/>
            <geometry>
                <mesh filename="package://robotik_kol_pkg/meshes/chain_link_grip_l.stl" scale="0.001 0.001 0.001"/>
            </geometry>
            <material name="grey">
                <color rgba="0.5 0.5 0.5 1.0"/>
            </material>
        </visual>

        <collision>
            <origin xyz="0.0 0.0 0" rpy="0 0 0"/>
            <geometry>
                <mesh filename="package://robotik_kol_pkg/meshes/chain_link_grip_l.stl" scale="0.001 0.001 0.001"/>
            </geometry>
        </collision>

        <inertial>
            <origin xyz="0 0 0"/>
            <mass value="1.0e-03"/>
            <inertia ixx="1.0e-03" ixy="0.0" ixz="0.0"
                     iyy="1.0e-03" iyz="0.0"
                     izz="1.0e-03"/>
        </inertial>
    </link>

    <!--  Gripper joint sub -->
    <joint name="gripper_sub" type="prismatic">
        <parent link="link5"/>
        <child link="gripper_link_sub"/>
        <origin xyz="0.0817 -0.021 0" rpy="0 0 0"/>
        <axis xyz="0 -1 0"/>
        <limit velocity="4.8" effort="1" lower="-0.010" upper="0.019"/>
        <mimic joint="gripper" multiplier="1"/>
    </joint>

    <!--  Gripper link sub -->
    <link name="gripper_link_sub">
        <visual>
            <origin xyz="0.0 -0.0 0" rpy="0 0 0"/>
            <geometry>
                <mesh filename="package://robotik_kol_pkg/meshes/chain_link_grip_r.stl" scale="0.001 0.001 0.001"/>
            </geometry>
            <material name="grey">
                <color rgba="0.5 0.5 0.5 1.0"/>
            </material>
        </visual>

        <collision>
            <origin xyz="0.0 -0.0 0" rpy="0 0 0"/>
            <geometry>
                <mesh filename="package://robotik_kol_pkg/meshes/chain_link_grip_r.stl" scale="0.001 0.001 0.001"/>
            </geometry>
        </collision>

        <inertial>
            <origin xyz="0 0 0"/>
            <mass value="1.0e-03"/>
            <inertia ixx="1.0e-03" ixy="0.0" ixz="0.0"
                     iyy="1.0e-03" iyz="0.0"
                     izz="1.0e-03"/>
        </inertial>
    </link>

    <!-- end effector joint -->
    <joint name="end_effector_joint" type="fixed">
        <origin xyz="0.126 0.0 0.0" rpy="0 0 0"/>
        <parent link="link5"/>
        <child link="end_effector_link"/>
    </joint>

    <!-- end effector link -->
    <link name="end_effector_link">
        <visual>
            <origin xyz="0 0 0" rpy="0 0 0"/>
            <geometry>
                <box size="0.01 0.01 0.01"/>
            </geometry>
            <material name="red">
                <color rgba="0.8 0.0 0.0 1.0"/>
            </material>
        </visual>

        <inertial>
            <origin xyz="0 0 0"/>
            <mass value="1.0e-03"/>
            <inertia ixx="1.0e-03" ixy="0.0" ixz="0.0"
                     iyy="1.0e-03" iyz="0.0"
                     izz="1.0e-03"/>
        </inertial>
    </link>

    <!-- Realsense Camera Joint Position -->
    <joint name="camera_joint" type="fixed">
        <axis xyz="0 1 0"/>
        <origin xyz="0.070 0.032 0.052" rpy="0 0 0"/>
        <parent link="link5"/>
        <child link="camera_link"/>
    </joint>

    <link name="camera_link"/>


    <xacro:macro name="RefLink" params="ref">
    <gazebo reference="${ref}">
      <kp>1000000.0</kp>
      <kd>100.0</kd>
      <mu1>30.0</mu1>
      <mu2>30.0</mu2>
      <maxVel>1.0</maxVel>
      <minDepth>0.001</minDepth>
      <material>Gazebo/DarkGrey</material>
    </gazebo>
  </xacro:macro>

  <!-- World -->
<<<<<<< HEAD
  <gazebo ref="world"/>
=======
  <gazebo reference="world"/>
>>>>>>> bec217401a3e4cc5acd7a5ab1d1549c9870abb62

  <!-- Link1 -->
  <RefLink ref="link1"/>

  <!-- Link2 -->
  <RefLink ref="link2"/>

  <!-- Link3 -->
  <RefLink ref="link3"/>

  <!-- Link4 -->
  <RefLink ref="link4"/>

  <!-- Link5 -->
  <RefLink ref="link5"/>

  <!-- gripper_link -->
  <RefLink ref="gripper_link"/>

  <!-- gripper_link_sub -->
  <RefLink ref="gripper_link_sub"/>

  <!-- end effector link -->
  <gazebo reference="end_effector_link">
    <material>Gazebo/Red</material>
  </gazebo>

  <!-- ros_control plugin -->
  <gazebo>
    <plugin name="gazebo_ros_control" filename="libgazebo_ros_control.so">
      <robotNamespace>/panda</robotNamespace>
      <controlPeriod>0.001</controlPeriod>
      <robotSimType>gazebo_ros_control/DefaultRobotHWSim</robotSimType>
      <legacyModeNS>true</legacyModeNS>
    </plugin>
  </gazebo>

  <gazebo>
    <!-- loading plugin: mimic joints works in gazebo now -->
    <plugin name="gazebo_gripper_ros_control" filename="libroboticsgroup_gazebo_mimic_joint_plugin.so">
      <robotNamespace>/panda</robotNamespace>
      <joint>gripper</joint>
      <mimicJoint>gripper_sub</mimicJoint>
      <multiplier>1.0</multiplier>
      <offset>0.0</offset>
    </plugin>
  </gazebo>

<<<<<<< HEAD
   <!--camera -->
    <!--gazebo reference="camera_link">
        <sensor type="camera" name="intel_realsense_r200">
            <update_rate>30.0</update_rate>
            <camera name="head">
                <horizontal_fov>1.02974</horizontal_fov>
                <image>
                    <width>1920</width>
                    <height>1080</height>
                    <format>R8G8B8</format>
                </image>
                <clip>
                    <near>0.02</near>
                    <far>300</far>
                </clip>
                <noise>
                    <type>gaussian</type>
                    <Noise is sampled independently per pixel on each frame. That pixel's noise value is added to each of its color channels, which at that point lie in the range [0,1].>
                    <mean>0.0</mean>
                    <stddev>0.007</stddev>
                </noise>
            </camera>
            <plugin name="camera_controller" filename="libgazebo_ros_camera.so">
                <robotNamespace>/panda</robotNamespace>
                <alwaysOn>true</alwaysOn>
                <updateRate>0.0</updateRate>
                <cameraName>camera/color</cameraName>
                <imageTopicName>image_raw</imageTopicName>
                <cameraInfoTopicName>camera_info</cameraInfoTopicName>
                <frameName>camera_link</frameName>
                <hackBaseline>0.07</hackBaseline>
                <distortionK1>0.0</distortionK1>
                <distortionK2>0.0</distortionK2>
                <distortionK3>0.0</distortionK3>
                <distortionT1>0.0</distortionT1>
                <distortionT2>0.0</distortionT2>
            </plugin>
        </sensor>
    </gazebo-->

</robot>
=======
  <!-- camera -->
  <gazebo reference="camera_link">
    <sensor type="camera" name="intel_realsense_r200">
      <update_rate>30.0</update_rate>
      <camera name="head">
        <horizontal_fov>1.02974</horizontal_fov>
        <image>
          <width>1920</width>
          <height>1080</height>
          <format>R8G8B8</format>
        </image>
        <clip>
          <near>0.02</near>
          <far>300</far>
        </clip>
        <noise>
          <type>gaussian</type>
          <!-- Noise is sampled independently per pixel on each frame.
               That pixel's noise value is added to each of its color
               channels, which at that point lie in the range [0,1]. -->
          <mean>0.0</mean>
          <stddev>0.007</stddev>
        </noise>
      </camera>
      <plugin name="camera_controller" filename="libgazebo_ros_camera.so">
        <robotNamespace>/panda</robotNamespace>
        <alwaysOn>true</alwaysOn>
        <updateRate>0.0</updateRate>
        <cameraName>camera/color</cameraName>
        <imageTopicName>image_raw</imageTopicName>
        <cameraInfoTopicName>camera_info</cameraInfoTopicName>
        <frameName>camera_link</frameName>
        <hackBaseline>0.07</hackBaseline>
        <distortionK1>0.0</distortionK1>
        <distortionK2>0.0</distortionK2>
        <distortionK3>0.0</distortionK3>
        <distortionT1>0.0</distortionT1>
        <distortionT2>0.0</distortionT2>
      </plugin>
    </sensor>
  </gazebo>



</robot>
>>>>>>> bec217401a3e4cc5acd7a5ab1d1549c9870abb62
